<?xml version="1.0"?>
<!--
Copyright (c) 2023 Michael Wimble

Permission is hereby granted, free of charge, to any person obtaining a copy
of this software and associated documentation files (the "Software"), to deal
in the Software without restriction, including without limitation the rights
to use, copy, modify, merge, publish, distribute, sublicense, and/or sell
copies of the Software, and to permit persons to whom the Software is
furnished to do so, subject to the following conditions:

The above copyright notice and this permission notice shall be included in all
copies or substantial portions of the Software.

THE SOFTWARE IS PROVIDED "AS IS", WITHOUT WARRANTY OF ANY KIND, EXPRESS OR
IMPLIED, INCLUDING BUT NOT LIMITED TO THE WARRANTIES OF MERCHANTABILITY,
FITNESS FOR A PARTICULAR PURPOSE AND NONINFRINGEMENT. IN NO EVENT SHALL THE
AUTHORS OR COPYRIGHT HOLDERS BE LIABLE FOR ANY CLAIM, DAMAGES OR OTHER
LIABILITY, WHETHER IN AN ACTION OF CONTRACT, TORT OR OTHERWISE, ARISING FROM,
OUT OF OR IN CONNECTION WITH THE SOFTWARE OR THE USE OR OTHER DEALINGS IN THE
SOFTWARE.
-->
<robot xmlns:xacro="http://ros.org/wiki/xacro" name="wheel">

	<xacro:macro name="wheel" params="wheel_prefix *joint_pose">
		<link name="${wheel_prefix}_wheel_link">
			<collision>
				<origin xyz="0 0 0" rpy="${M_PI/2} 0 0" />
				<geometry>
					<cylinder length="${wheel_width}" radius="${wheel_radius}" />
				</geometry>
			</collision>
			<inertial>
				<mass value="2.637" />
				<origin xyz="0 0 0" />
				<inertia ixx="0.02467" ixy="0" ixz="0" iyy="0.04411" iyz="0" izz="0.02467" />
			</inertial>
			<visual>
				<origin xyz="0 0 0" rpy="${M_PI/2} 0 0" />
				<geometry>
					<cylinder length="${wheel_width}" radius="${wheel_radius}" />
				</geometry>
				<material name="wheel_material" />
			</visual>
		</link>

		<joint name="${wheel_prefix}_wheel_joint" type="continuous">
			<parent link="base_link" />
			<child link="${wheel_prefix}_wheel_link" />
			<xacro:insert_block name="joint_pose" />
			<axis xyz="0 1 0" rpy="0 0 0" />
			<limit effort="100" velocity="3" />
			<dynamics damping="0.1" friction="0.5" />
		</joint>

		<gazebo reference="${wheel_prefix}_wheel_link">
			<mu1 value="10000.0" />
			<mu2 value="10000.0" />
			<kp value="1e13" />
			<kd value="1" />
			<!-- <mu1>200.0</mu1>
			<mu2>100.0</mu2>
			<kp>1000000.0</kp>
			<kd>1.0</kd>
			<max_vel>0.01</max_vel>
			<min_depth>0.001</min_depth> -->
			<material>Gazebo/Black</material>
		</gazebo>
	</xacro:macro>

</robot>